<!DOCTYPE html>
<html lang="en">

<head>
    <meta charset="UTF-8">
    <meta name="viewport" content="width=device-width, initial-scale=1.0">
    <meta http-equiv="X-UA-Compatible" content="ie=edge">
    <title>Document</title>
</head>

<body>
    <script>
        function getNumber() {
            var p = new Promise(function (resolve, reject) {
                //做一些异步操作
                setTimeout(function () {
                    var num = Math.ceil(Math.random() * 10); //生成1-10的随机数
                    if (num <= 5) {
                        resolve(num);
                    } else {
                        reject('数字太大了');
                    }
                }, 1000);
            });
            return p;
        }

        //catch作用一：和then的第二个回掉函数一样
        // getNumber()
        //     .then(function (data) {
        //         console.log('resolved');
        //         console.log(data);
        //     })
        //     .catch(function (reason) {
        //         console.log('rejected');
        //         console.log(reason);
        //     });

        //catch作用二：在执行then的第一个回掉时，如果抛出异常了（代码出错），并不会卡死js，而是会进到这个catch方法中，而且把错误原因传到了reason参数中（传给catch的回掉函数的参数）
        getNumber()
            .then(function (data) {
                console.log('resolved');
                console.log(data);
                console.log(somedata); //此处的somedata未定义，出错
            })
            .catch(function (reason) {
                console.log('rejected');
                console.log(reason);
            });
    </script>
</body>

</html>